2019-04-03 09:37:32,542 ERROR 8896 nodejs.ClusterClientNoResponseError: client no response in 3907399ms exceeding maxIdleTime 60000ms, maybe the connection is close on other side.
    at Timeout.Leader._heartbeatTimer.setInterval [as _onTimeout] (C:\Users\Administrator\Desktop\API\node_modules\cluster-client\lib\leader.js:77:23)
    at ontimeout (timers.js:436:11)
    at tryOnTimeout (timers.js:300:5)
    at listOnTimeout (timers.js:263:5)
    at Timer.processTimers (timers.js:223:10)
name: "ClusterClientNoResponseError"
pid: 8896
hostname: 20161212-102137

2019-04-03 14:08:50,276 ERROR 8896 nodejs.ClusterClientNoResponseError: client no response in 2266987ms exceeding maxIdleTime 60000ms, maybe the connection is close on other side.
    at Timeout.Leader._heartbeatTimer.setInterval [as _onTimeout] (C:\Users\Administrator\Desktop\API\node_modules\cluster-client\lib\leader.js:77:23)
    at ontimeout (timers.js:436:11)
    at tryOnTimeout (timers.js:300:5)
    at listOnTimeout (timers.js:263:5)
    at Timer.processTimers (timers.js:223:10)
name: "ClusterClientNoResponseError"
pid: 8896
hostname: 20161212-102137

2019-04-03 15:12:34,078 ERROR 13524 [-/127.0.0.1/-/36ms POST /backend/v1/upload/upload] nodejs.TypeError: this.ServerResponse.createBySuccess is not a function
    at UploadApiController.saveFile (C:\Users\Administrator\Desktop\API\app\controller\backend\uploadapicontroller.js:37:34)
    at process._tickCallback (internal/process/next_tick.js:68:7)
headers: {"Access-Control-Allow-Origin":"*","Access-Control-Allow-Credentials":"true","vary":"Origin"}
pid: 13524
hostname: 20161212-102137

2019-04-03 15:12:34,096 ERROR 13524 nodejs.ENOENTError: ENOENT: no such file or directory, open 'C:\Users\Administrator\Desktop\API\app\public\upload\image\微信图片_201901291418351554275554057.png' (uncaughtException throw 1 times on pid:13524)
ENOENTError: ENOENT: no such file or directory, open 'C:\Users\Administrator\Desktop\API\app\public\upload\image\微信图片_201901291418351554275554057.png' (uncaughtException throw 1 times on pid:13524)
errno: -4058
code: "ENOENT"
syscall: "open"
path: "C:\\Users\\Administrator\\Desktop\\API\\app\\public\\upload\\image\\微信图片_201901291418351554275554057.png"
name: "ENOENTError"
pid: 13524
hostname: 20161212-102137

2019-04-03 15:15:17,530 ERROR 12432 nodejs.ENOENTError: ENOENT: no such file or directory, open 'C:\Users\Administrator\Desktop\API\app\public\upload\image\微信图片_201901291418351554275717508.png' (uncaughtException throw 1 times on pid:12432)
ENOENTError: ENOENT: no such file or directory, open 'C:\Users\Administrator\Desktop\API\app\public\upload\image\微信图片_201901291418351554275717508.png' (uncaughtException throw 1 times on pid:12432)
errno: -4058
code: "ENOENT"
syscall: "open"
path: "C:\\Users\\Administrator\\Desktop\\API\\app\\public\\upload\\image\\微信图片_201901291418351554275717508.png"
name: "ENOENTError"
pid: 12432
hostname: 20161212-102137

2019-04-03 15:39:28,229 ERROR 7696 nodejs.ENOENTError: ENOENT: no such file or directory, open 'C:\Users\Administrator\Desktop\API\app\public\upload\image\pzhuBBS1554277168203.png' (uncaughtException throw 1 times on pid:7696)
ENOENTError: ENOENT: no such file or directory, open 'C:\Users\Administrator\Desktop\API\app\public\upload\image\pzhuBBS1554277168203.png' (uncaughtException throw 1 times on pid:7696)
errno: -4058
code: "ENOENT"
syscall: "open"
path: "C:\\Users\\Administrator\\Desktop\\API\\app\\public\\upload\\image\\pzhuBBS1554277168203.png"
name: "ENOENTError"
pid: 7696
hostname: 20161212-102137

2019-04-03 15:49:16,423 ERROR 7396 nodejs.ENOENTError: ENOENT: no such file or directory, open 'C:\Users\Administrator\Desktop\API\app\public\upload\image\pzhuBBS1554277756417.png' (uncaughtException throw 1 times on pid:7396)
ENOENTError: ENOENT: no such file or directory, open 'C:\Users\Administrator\Desktop\API\app\public\upload\image\pzhuBBS1554277756417.png' (uncaughtException throw 1 times on pid:7396)
errno: -4058
code: "ENOENT"
syscall: "open"
path: "C:\\Users\\Administrator\\Desktop\\API\\app\\public\\upload\\image\\pzhuBBS1554277756417.png"
name: "ENOENTError"
pid: 7396
hostname: 20161212-102137

2019-04-04 12:29:12,446 ERROR 9520 nodejs.ClusterClientNoResponseError: client no response in 798556ms exceeding maxIdleTime 60000ms, maybe the connection is close on other side.
    at Timeout.Leader._heartbeatTimer.setInterval [as _onTimeout] (C:\Users\Administrator\Desktop\API\node_modules\cluster-client\lib\leader.js:77:23)
    at ontimeout (timers.js:436:11)
    at tryOnTimeout (timers.js:300:5)
    at listOnTimeout (timers.js:263:5)
    at Timer.processTimers (timers.js:223:10)
name: "ClusterClientNoResponseError"
pid: 9520
hostname: 20161212-102137

2019-04-04 14:05:27,004 ERROR 9520 nodejs.ClusterClientNoResponseError: client no response in 1467159ms exceeding maxIdleTime 60000ms, maybe the connection is close on other side.
    at Timeout.Leader._heartbeatTimer.setInterval [as _onTimeout] (C:\Users\Administrator\Desktop\API\node_modules\cluster-client\lib\leader.js:77:23)
    at ontimeout (timers.js:436:11)
    at tryOnTimeout (timers.js:300:5)
    at listOnTimeout (timers.js:263:5)
    at Timer.processTimers (timers.js:223:10)
name: "ClusterClientNoResponseError"
pid: 9520
hostname: 20161212-102137

2019-04-12 07:50:29,203 ERROR 13268 nodejs.ClusterClientNoResponseError: client no response in 44691212ms exceeding maxIdleTime 60000ms, maybe the connection is close on other side.
    at Timeout.Leader._heartbeatTimer.setInterval [as _onTimeout] (C:\Users\Administrator\Desktop\API\node_modules\cluster-client\lib\leader.js:77:23)
    at ontimeout (timers.js:436:11)
    at tryOnTimeout (timers.js:300:5)
    at listOnTimeout (timers.js:263:5)
    at Timer.processTimers (timers.js:223:10)
name: "ClusterClientNoResponseError"
pid: 13268
hostname: 20161212-102137

